Workbook

Sheet Overview
C1: Installed capacity per scenario [GWh, GW or tCO2/hour] | G1: Produced energy per scenario [GWh, Million kilometers, tCO2] | K1: Non-prospective LCA database information | U1: Prospective LCA database information | AD1: EF v3.1 SSP2-Base | AT1: Results v3.1 SSP2-Base EP2050+ | BJ1: Results v3.1 SSP2-Base MIX | BZ1: Results v3.1 SSP2-Base RE MIX | CP1: EF v3.1 SSP2-PkBudg1150
A2: Calliope technology | B2: Real life name | C2: EP2050+ | D2: MIX | E2: RE MIX | F2: H2 Imports | G2: EP2050+ | H2: MIX | I2: RE MIX | J2: H2 Imports | K2: Database | L2: Activity name | M2: Activity Code | N2: Location | O2: Unit of the technology in LCA | P2: Quantity for Calliope | Q2: Carrier for energy production | R2: Special instructions for ecoinvent data | S2: Inputs which were removed | T2: Comment | U2: Activity name | V2: Activity Code | W2: Location | X2: Location of impact | Y2: Unit of the dataset | Z2: conversion factor to GWh or GW | AA2: conversion factor to Million kilometers | AB2: conversion factor to t CO2 | AC2: unit of conversion factor | AD2: climate change [kg CO2-eq. per unit of dataset] | AE2: particular matter formation [disease incidence per unit of dataset] | AF2: photochemical oxidant [kg NMVOC-eq. per unit of dataset] | AG2: marine eutrophication [kg N-eq. per unit of dataset] | AH2: terrestrial eutrophication [mol N-eq. per unit of dataset] | AI2: freshwater eutrophication [kg P-eq. per unit of dataset] | AJ2: acidification [mol H+-eq. per unit of dataset] | AK2: human toxicity: non-carcinogenic [CTUh per unit of dataset] | AL2: humantoxicity: carcinogenic [CTUh per unit of dataset] | AM2: freshwater ecotoxicity [CTUe per unit of dataset] | AN2: energy ressources (non renewable) [MJ, net calorific value per unit of dataset] | AO2: material resources: metals/minerals [kg Sb-eq. per unit of dataset] | AP2: ozone depletion [kg CFC-11-eq. per unit of dataset] | AQ2: ionising radiation: human health [kBq U235-eq. per unit of dataset] | AR2: land use [no dimension per unit of dataset] | AS2: water use [m3 world eq. deprived per unit of dataset] | AT2: climate change [kg CO2-eq.] | AU2: particular matter formation [disease incidence] | AV2: photochemical oxidant [kg NMVOC-eq.] | AW2: marine eutrophication [kg N-eq.] | AX2: terrestrial eutrophication [mol N-eq.] | AY2: freshwater eutrophication [kg P-eq.] | AZ2: acidification [mol H+-eq.] | BA2: human toxicity: non-carcinogenic [CTUh] | BB2: humantoxicity: carcinogenic [CTUh] | BC2: freshwater ecotoxicity [CTUe] | BD2: energy ressources (non renewable) [MJ, net calorific value] | BE2: material resources: metals/minerals [kg Sb-eq.] | BF2: ozone depletion [kg CFC-11-eq.] | BG2: ionisinng radiation: human health [kBq U235-eq.] | BH2: land use [no dimension] | BI2: water use [m3 world eq. Deprived] | BJ2: climate change [kg CO2-eq.] | BK2: particular matter formation [disease incidence] | BL2: photochemical oxidant [kg NMVOC-eq.] | BM2: marine eutrophication [kg N-eq.] | BN2: terrestrial eutrophication [mol N-eq.] | BO2: freshwater eutrophication [kg P-eq.] | BP2: acidification [mol H+-eq.] | BQ2: human toxicity: non-carcinogenic [CTUh] | BR2: humantoxicity: carcinogenic [CTUh] | BS2: freshwater ecotoxicity [CTUe] | BT2: energy ressources (non renewable) [MJ, net calorific value] | BU2: material resources: metals/minerals [kg Sb-eq.] | BV2: ozone depletion [kg CFC-11-eq.] | BW2: ionisinng radiation: human health [kBq U235-eq.] | BX2: land use [no dimension] | BY2: water use [m3 world eq. Deprived] | BZ2: climate change [kg CO2-eq.] | CA2: particular matter formation [disease incidence] | CB2: photochemical oxidant [kg NMVOC-eq.] | CC2: marine eutrophication [kg N-eq.] | CD2: terrestrial eutrophication [mol N-eq.] | CE2: freshwater eutrophication [kg P-eq.] | CF2: acidification [mol H+-eq.] | CG2: human toxicity: non-carcinogenic [CTUh] | CH2: humantoxicity: carcinogenic [CTUh] | CI2: freshwater ecotoxicity [CTUe] | CJ2: energy ressources (non renewable) [MJ, net calorific value] | CK2: material resources: metals/minerals [kg Sb-eq.] | CL2: ozone depletion [kg CFC-11-eq.] | CM2: ionisinng radiation: human health [kBq U235-eq.] | CN2: land use [no dimension] | CO2: water use [m3 world eq. Deprived] | CP2: climate change [kg CO2-eq. per unit of dataset] | CQ2: particular matter formation [disease incidence per unit of dataset] | CR2: photochemical oxidant [kg NMVOC-eq. per unit of dataset] | CS2: marine eutrophication [kg N-eq. per unit of dataset] | CT2: terrestrial eutrophication [mol N-eq. per unit of dataset] | CU2: freshwater eutrophication [kg P-eq. per unit of dataset] | CV2: acidification [mol H+-eq. per unit of dataset] | CW2: human toxicity: non-carcinogenic [CTUh per unit of dataset] | CX2: humantoxicity: carcinogenic [CTUh per unit of dataset] | CY2: freshwater ecotoxicity [CTUe per unit of dataset] | CZ2: energy ressources (non renewable) [MJ, net calorific value per unit of dataset] | DA2: material resources: metals/minerals [kg Sb-eq. per unit of dataset] | DB2: ozone depletion [kg CFC-11-eq. per unit of dataset] | DC2: ionising radiation: human health [kBq U235-eq. per unit of dataset] | DD2: land use [no dimension per unit of dataset] | DE2: water use [m3 world eq. deprived per unit of dataset]
A4: battery | B4: Grid storage batteries | C4: 0.00011810939 | D4: 9.5158326e-06 | E4: 2.7873239e-05 | F4: 0.00021582062 | G4: 0.12031879 | H4: 0.025921036 | I4: 0.05699462 | J4: 0.34297312 | K4: ecoinvent 3.9.1 | L4: battery production, Li-ion, NMC811, rechargeable, prismatic | M4: 0f8c132a27a299fb959c5e35254f4861 | N4: CN | O4: 1.0 kilogram | P4: storage_cap | Q4: electricity | R4: assuming 23.53 kWh / 158 kg of battery Lifetime of 10 years | S4: - | T4: - | U4: battery production, Li-ion, NMC811, rechargeable, prismatic | V4: 0f8c132a27a299fb959c5e35254f4861 | W4: CN | X4: Abroad | Y4: kg | Z4: =158/23.53*1000000 -> 6714832.1 | AC4: kg/GWh | AD4: =SUMIF(#REF!,Overview!U4,#REF!) -> #REF! | AE4: =SUMIF(#REF!,Overview!U4,#REF!) -> #REF! | AF4: =SUMIF(#REF!,Overview!U4,#REF!) -> #REF! | AG4: =SUMIF(#REF!,Overview!U4,#REF!) -> #REF! | AH4: =SUMIF(#REF!,Overview!U4,#REF!) -> #REF! | AI4: =SUMIF(#REF!,Overview!U4,#REF!) -> #REF! | AJ4: =SUMIF(#REF!,Overview!U4,#REF!) -> #REF! | AK4: =SUMIF(#REF!,Overview!U4,#REF!) -> #REF! | AL4: =SUMIF(#REF!,Overview!U4,#REF!) -> #REF! | AM4: =SUMIF(#REF!,Overview!U4,#REF!) -> #REF! | AN4: =SUMIF(#REF!,Overview!U4,#REF!) -> #REF! | AO4: =SUMIF(#REF!,Overview!U4,#REF!) -> #REF! | AP4: =SUMIF(#REF!,Overview!U4,#REF!) -> #REF! | AQ4: =SUMIF(#REF!,Overview!U4,#REF!) -> #REF! | AR4: =SUMIF(#REF!,Overview!U4,#REF!) -> #REF! | AS4: =SUMIF(#REF!,Overview!U4,#REF!) -> #REF! | AT4: =AD4*$Z4*$C4/10 -> #REF! | AU4: =AE4*$Z4*$C4/10 -> #REF! | AV4: =AF4*$Z4*$C4/10 -> #REF! | AW4: =AG4*$Z4*$C4/10 -> #REF! | AX4: =AH4*$Z4*$C4/10 -> #REF! | AY4: =AI4*$Z4*$C4/10 -> #REF! | AZ4: =AJ4*$Z4*$C4/10 -> #REF! | BA4: =AK4*$Z4*$C4/10 -> #REF! | ... BI4: =AS4*$Z4*$C4/10 -> #REF! | BJ4: =AD4*$Z4*$D4/10 -> #REF! | BK4: =AE4*$Z4*$D4/10 -> #REF! | BL4: =AF4*$Z4*$D4/10 -> #REF! | BM4: =AG4*$Z4*$D4/10 -> #REF! | BN4: =AH4*$Z4*$D4/10 -> #REF! | BO4: =AI4*$Z4*$D4/10 -> #REF! | BP4: =AJ4*$Z4*$D4/10 -> #REF! | BQ4: =AK4*$Z4*$D4/10 -> #REF! | ... BY4: =AS4*$Z4*$D4/10 -> #REF! | BZ4: =AD4*$Z4*$E4/10 -> #REF! | CA4: =AE4*$Z4*$E4/10 -> #REF! | CB4: =AF4*$Z4*$E4/10 -> #REF! | CC4: =AG4*$Z4*$E4/10 -> #REF! | CD4: =AH4*$Z4*$E4/10 -> #REF! | CE4: =AI4*$Z4*$E4/10 -> #REF! | CF4: =AJ4*$Z4*$E4/10 -> #REF! | CG4: =AK4*$Z4*$E4/10 -> #REF! | ... CO4: =AS4*$Z4*$E4/10 -> #REF! | CP4: =SUMIF(#REF!,Overview!$U4,#REF!) -> #REF! | CQ4: =SUMIF(#REF!,Overview!$U4,#REF!) -> #REF! | CR4: =SUMIF(#REF!,Overview!$U4,#REF!) -> #REF! | CS4: =SUMIF(#REF!,Overview!$U4,#REF!) -> #REF! | CT4: =SUMIF(#REF!,Overview!$U4,#REF!) -> #REF! | CU4: =SUMIF(#REF!,Overview!$U4,#REF!) -> #REF! | CV4: =SUMIF(#REF!,Overview!$U4,#REF!) -> #REF! | CW4: =SUMIF(#REF!,Overview!$U4,#REF!) -> #REF! | ... DE4: =SUMIF(#REF!,Overview!$U4,#REF!) -> #REF!
B5: Biofuel to biofuel boiler | G5: 38498 | R5: LHV of 19MJ/kg | U5: market for biomass, used as fuel | V5: 0c1c787fe88d4390a27b37129e314b49 | W5: EUR | X5: CH | Y5: kg | Z5: =3.6*1000000/19 -> 189473.68 | AC5: kg/GWh | AD5: =SUMIF(#REF!,Overview!U5,#REF!) -> #REF! | AE5: =SUMIF(#REF!,Overview!U5,#REF!) -> #REF! | AF5: =SUMIF(#REF!,Overview!U5,#REF!) -> #REF! | AG5: =SUMIF(#REF!,Overview!U5,#REF!) -> #REF! | AH5: =SUMIF(#REF!,Overview!U5,#REF!) -> #REF! | AI5: =SUMIF(#REF!,Overview!U5,#REF!) -> #REF! | AJ5: =SUMIF(#REF!,Overview!U5,#REF!) -> #REF! | AK5: =SUMIF(#REF!,Overview!U5,#REF!) -> #REF! | AL5: =SUMIF(#REF!,Overview!U5,#REF!) -> #REF! | AM5: =SUMIF(#REF!,Overview!U5,#REF!) -> #REF! | AN5: =SUMIF(#REF!,Overview!U5,#REF!) -> #REF! | AO5: =SUMIF(#REF!,Overview!U5,#REF!) -> #REF! | AP5: =SUMIF(#REF!,Overview!U5,#REF!) -> #REF! | AQ5: =SUMIF(#REF!,Overview!U5,#REF!) -> #REF! | AR5: =SUMIF(#REF!,Overview!U5,#REF!) -> #REF! | AS5: =SUMIF(#REF!,Overview!U5,#REF!) -> #REF! | AT5: =AD5*$Z5*$G5 -> #REF! | AU5: =AE5*$Z5*$G5 -> #REF! | AV5: =AF5*$Z5*$G5 -> #REF! | AW5: =AG5*$Z5*$G5 -> #REF! | AX5: =AH5*$Z5*$G5 -> #REF! | AY5: =AI5*$Z5*$G5 -> #REF! | AZ5: =AJ5*$Z5*$G5 -> #REF! | BA5: =AK5*$Z5*$G5 -> #REF! | ... BI5: =AS5*$Z5*$G5 -> #REF! | CP5: =SUMIF(#REF!,Overview!$U5,#REF!) -> #REF! | CQ5: =SUMIF(#REF!,Overview!$U5,#REF!) -> #REF! | CR5: =SUMIF(#REF!,Overview!$U5,#REF!) -> #REF! | CS5: =SUMIF(#REF!,Overview!$U5,#REF!) -> #REF! | CT5: =SUMIF(#REF!,Overview!$U5,#REF!) -> #REF! | CU5: =SUMIF(#REF!,Overview!$U5,#REF!) -> #REF! | CV5: =SUMIF(#REF!,Overview!$U5,#REF!) -> #REF! | CW5: =SUMIF(#REF!,Overview!$U5,#REF!) -> #REF! | ... DE5: =SUMIF(#REF!,Overview!$U5,#REF!) -> #REF!
B6: Biofuel to biofuel to methane | G6: 2413 | R6: LHV of 19MJ/kg | U6: market for biomass, used as fuel | V6: 0c1c787fe88d4390a27b37129e314b49 | W6: EUR | X6: CH | Y6: kg | Z6: =3.6*1000000/19 -> 189473.68 | AC6: kg/GWh | AD6: =SUMIF(#REF!,Overview!U6,#REF!) -> #REF! | AE6: =SUMIF(#REF!,Overview!U6,#REF!) -> #REF! | AF6: =SUMIF(#REF!,Overview!U6,#REF!) -> #REF! | AG6: =SUMIF(#REF!,Overview!U6,#REF!) -> #REF! | AH6: =SUMIF(#REF!,Overview!U6,#REF!) -> #REF! | AI6: =SUMIF(#REF!,Overview!U6,#REF!) -> #REF! | AJ6: =SUMIF(#REF!,Overview!U6,#REF!) -> #REF! | AK6: =SUMIF(#REF!,Overview!U6,#REF!) -> #REF! | AL6: =SUMIF(#REF!,Overview!U6,#REF!) -> #REF! | AM6: =SUMIF(#REF!,Overview!U6,#REF!) -> #REF! | AN6: =SUMIF(#REF!,Overview!U6,#REF!) -> #REF! | AO6: =SUMIF(#REF!,Overview!U6,#REF!) -> #REF! | AP6: =SUMIF(#REF!,Overview!U6,#REF!) -> #REF! | AQ6: =SUMIF(#REF!,Overview!U6,#REF!) -> #REF! | AR6: =SUMIF(#REF!,Overview!U6,#REF!) -> #REF! | AS6: =SUMIF(#REF!,Overview!U6,#REF!) -> #REF! | AT6: =AD6*$Z6*$G6 -> #REF! | AU6: =AE6*$Z6*$G6 -> #REF! | AV6: =AF6*$Z6*$G6 -> #REF! | AW6: =AG6*$Z6*$G6 -> #REF! | AX6: =AH6*$Z6*$G6 -> #REF! | AY6: =AI6*$Z6*$G6 -> #REF! | AZ6: =AJ6*$Z6*$G6 -> #REF! | BA6: =AK6*$Z6*$G6 -> #REF! | ... BI6: =AS6*$Z6*$G6 -> #REF! | CP6: =SUMIF(#REF!,Overview!$U6,#REF!) -> #REF! | CQ6: =SUMIF(#REF!,Overview!$U6,#REF!) -> #REF! | CR6: =SUMIF(#REF!,Overview!$U6,#REF!) -> #REF! | CS6: =SUMIF(#REF!,Overview!$U6,#REF!) -> #REF! | CT6: =SUMIF(#REF!,Overview!$U6,#REF!) -> #REF! | CU6: =SUMIF(#REF!,Overview!$U6,#REF!) -> #REF! | CV6: =SUMIF(#REF!,Overview!$U6,#REF!) -> #REF! | CW6: =SUMIF(#REF!,Overview!$U6,#REF!) -> #REF! | ... DE6: =SUMIF(#REF!,Overview!$U6,#REF!) -> #REF!
B7: Biofuel to biofuel boiler (ind.) | G7: 89 | R7: LHV of 19MJ/kg | U7: market for biomass, used as fuel | V7: 0c1c787fe88d4390a27b37129e314b49 | W7: EUR | X7: CH | Y7: kg | Z7: =3.6*1000000/19 -> 189473.68 | AC7: kg/GWh | AD7: =SUMIF(#REF!,Overview!U7,#REF!) -> #REF! | AE7: =SUMIF(#REF!,Overview!U7,#REF!) -> #REF! | AF7: =SUMIF(#REF!,Overview!U7,#REF!) -> #REF! | AG7: =SUMIF(#REF!,Overview!U7,#REF!) -> #REF! | AH7: =SUMIF(#REF!,Overview!U7,#REF!) -> #REF! | AI7: =SUMIF(#REF!,Overview!U7,#REF!) -> #REF! | AJ7: =SUMIF(#REF!,Overview!U7,#REF!) -> #REF! | AK7: =SUMIF(#REF!,Overview!U7,#REF!) -> #REF! | AL7: =SUMIF(#REF!,Overview!U7,#REF!) -> #REF! | AM7: =SUMIF(#REF!,Overview!U7,#REF!) -> #REF! | AN7: =SUMIF(#REF!,Overview!U7,#REF!) -> #REF! | AO7: =SUMIF(#REF!,Overview!U7,#REF!) -> #REF! | AP7: =SUMIF(#REF!,Overview!U7,#REF!) -> #REF! | AQ7: =SUMIF(#REF!,Overview!U7,#REF!) -> #REF! | AR7: =SUMIF(#REF!,Overview!U7,#REF!) -> #REF! | AS7: =SUMIF(#REF!,Overview!U7,#REF!) -> #REF! | AT7: =AD7*$Z7*$G7 -> #REF! | AU7: =AE7*$Z7*$G7 -> #REF! | AV7: =AF7*$Z7*$G7 -> #REF! | AW7: =AG7*$Z7*$G7 -> #REF! | AX7: =AH7*$Z7*$G7 -> #REF! | AY7: =AI7*$Z7*$G7 -> #REF! | AZ7: =AJ7*$Z7*$G7 -> #REF! | BA7: =AK7*$Z7*$G7 -> #REF! | ... BI7: =AS7*$Z7*$G7 -> #REF! | CP7: =SUMIF(#REF!,Overview!$U7,#REF!) -> #REF! | CQ7: =SUMIF(#REF!,Overview!$U7,#REF!) -> #REF! | CR7: =SUMIF(#REF!,Overview!$U7,#REF!) -> #REF! | CS7: =SUMIF(#REF!,Overview!$U7,#REF!) -> #REF! | CT7: =SUMIF(#REF!,Overview!$U7,#REF!) -> #REF! | CU7: =SUMIF(#REF!,Overview!$U7,#REF!) -> #REF! | CV7: =SUMIF(#REF!,Overview!$U7,#REF!) -> #REF! | CW7: =SUMIF(#REF!,Overview!$U7,#REF!) -> #REF! | ... DE7: =SUMIF(#REF!,Overview!$U7,#REF!) -> #REF!
A8: biofuel_to_diesel | B8: Biodiesel production | C8: 3.8553643e-06 | D8: 0 | E8: 0 | F8: 6.2196363e-06 | G8: 0.0096920117 | H8: 0 | I8: 0.010014449 | J8: 0.012292228 | K8: ecoinvent 3.9.1 | L8: esterification of vegetable oils and animal fats, average mix | M8: 82feb4582c0938c6ac7d1c78319dae7d | N8: BR | O8: 1.0 kilogram | P8: carrier_prod | Q8: diesel | R8: Multiply by 43 / 3.6e6 to obtain GWh / kg, assuming LHV of 43 MJ / kg so 43 / 3.6e6 GWh/kg Lifetime of 20 years | S8: soybean meal and crude oil production (location : BR) | market for cottonseed oil, crude (location : GLO) | T8: - | U8: esterification of vegetable oils and animal fats, average mix, Calliope | V8: 82feb4582c0938c6ac7d1c78319dae7d | W8: BR | X8: CH | Y8: kg | Z8: =3.6*1000000/43 -> 83720.93 | AC8: kg/GWh | AD8: =SUMIF(#REF!,Overview!U8,#REF!) -> #REF! | AE8: =SUMIF(#REF!,Overview!U8,#REF!) -> #REF! | AF8: =SUMIF(#REF!,Overview!U8,#REF!) -> #REF! | AG8: =SUMIF(#REF!,Overview!U8,#REF!) -> #REF! | AH8: =SUMIF(#REF!,Overview!U8,#REF!) -> #REF! | AI8: =SUMIF(#REF!,Overview!U8,#REF!) -> #REF! | AJ8: =SUMIF(#REF!,Overview!U8,#REF!) -> #REF! | AK8: =SUMIF(#REF!,Overview!U8,#REF!) -> #REF! | AL8: =SUMIF(#REF!,Overview!U8,#REF!) -> #REF! | AM8: =SUMIF(#REF!,Overview!U8,#REF!) -> #REF! | AN8: =SUMIF(#REF!,Overview!U8,#REF!) -> #REF! | AO8: =SUMIF(#REF!,Overview!U8,#REF!) -> #REF! | AP8: =SUMIF(#REF!,Overview!U8,#REF!) -> #REF! | AQ8: =SUMIF(#REF!,Overview!U8,#REF!) -> #REF! | AR8: =SUMIF(#REF!,Overview!U8,#REF!) -> #REF! | AS8: =SUMIF(#REF!,Overview!U8,#REF!) -> #REF! | AT8: =AD8*$Z8*$G8 -> #REF! | AU8: =AE8*$Z8*$G8 -> #REF! | AV8: =AF8*$Z8*$G8 -> #REF! | AW8: =AG8*$Z8*$G8 -> #REF! | AX8: =AH8*$Z8*$G8 -> #REF! | AY8: =AI8*$Z8*$G8 -> #REF! | AZ8: =AJ8*$Z8*$G8 -> #REF! | BA8: =AK8*$Z8*$G8 -> #REF! | ... BI8: =AS8*$Z8*$G8 -> #REF! | BJ8: =AD8*$Z8*$H8 -> #REF! | BK8: =AE8*$Z8*$H8 -> #REF! | BL8: =AF8*$Z8*$H8 -> #REF! | BM8: =AG8*$Z8*$H8 -> #REF! | BN8: =AH8*$Z8*$H8 -> #REF! | BO8: =AI8*$Z8*$H8 -> #REF! | BP8: =AJ8*$Z8*$H8 -> #REF! | BQ8: =AK8*$Z8*$H8 -> #REF! | ... BY8: =AS8*$Z8*$H8 -> #REF! | BZ8: =AD8*$Z8*$I8 -> #REF! | CA8: =AE8*$Z8*$I8 -> #REF! | CB8: =AF8*$Z8*$I8 -> #REF! | CC8: =AG8*$Z8*$I8 -> #REF! | CD8: =AH8*$Z8*$I8 -> #REF! | CE8: =AI8*$Z8*$I8 -> #REF! | CF8: =AJ8*$Z8*$I8 -> #REF! | CG8: =AK8*$Z8*$I8 -> #REF! | ... CO8: =AS8*$Z8*$I8 -> #REF! | CP8: =SUMIF(#REF!,Overview!$U8,#REF!) -> #REF! | CQ8: =SUMIF(#REF!,Overview!$U8,#REF!) -> #REF! | CR8: =SUMIF(#REF!,Overview!$U8,#REF!) -> #REF! | CS8: =SUMIF(#REF!,Overview!$U8,#REF!) -> #REF! | CT8: =SUMIF(#REF!,Overview!$U8,#REF!) -> #REF! | CU8: =SUMIF(#REF!,Overview!$U8,#REF!) -> #REF! | CV8: =SUMIF(#REF!,Overview!$U8,#REF!) -> #REF! | CW8: =SUMIF(#REF!,Overview!$U8,#REF!) -> #REF! | ... DE8: =SUMIF(#REF!,Overview!$U8,#REF!) -> #REF!
A9: biofuel_to_methane | B9: Biomethane production | C9: 0.19229255 | D9: 0 | E9: 1.5459477 | F9: 2.4600906e-06 | G9: 1689.0953 | H9: 0.0056005361 | I9: 13579.551 | J9: 0.016739178 | K9: ecoinvent 3.9.1 | L9: biomethane production, high pressure from synthetic gas, wood, fluidised technology | M9: 02fbdebc28ae8a5bf87f167e0797c8da | N9: CH | O9: 1.0 cubic meter | P9: carrier_prod | Q9: methane | R9: Multiply by 34.4 / 3.6e6 to obtain GWh / m3, assuming LHV = 34.4 MJ / Nm3 = 34.4 / 3.6e6 GWh/Nm3 Lifetime of 20 years | S9: - | T9: - | U9: biomethane production, high pressure from synthetic gas, wood, fluidised technology | V9: 02fbdebc28ae8a5bf87f167e0797c8da | W9: CH | X9: CH | Y9: m3 | Z9: =3.6*1000000/34.4 -> 104651.16 | AC9: m3/GWh | AD9: =SUMIF(#REF!,Overview!U9,#REF!) -> #REF! | AE9: =SUMIF(#REF!,Overview!U9,#REF!) -> #REF! | AF9: =SUMIF(#REF!,Overview!U9,#REF!) -> #REF! | AG9: =SUMIF(#REF!,Overview!U9,#REF!) -> #REF! | AH9: =SUMIF(#REF!,Overview!U9,#REF!) -> #REF! | AI9: =SUMIF(#REF!,Overview!U9,#REF!) -> #REF! | AJ9: =SUMIF(#REF!,Overview!U9,#REF!) -> #REF! | AK9: =SUMIF(#REF!,Overview!U9,#REF!) -> #REF! | AL9: =SUMIF(#REF!,Overview!U9,#REF!) -> #REF! | AM9: =SUMIF(#REF!,Overview!U9,#REF!) -> #REF! | AN9: =SUMIF(#REF!,Overview!U9,#REF!) -> #REF! | AO9: =SUMIF(#REF!,Overview!U9,#REF!) -> #REF! | AP9: =SUMIF(#REF!,Overview!U9,#REF!) -> #REF! | AQ9: =SUMIF(#REF!,Overview!U9,#REF!) -> #REF! | AR9: =SUMIF(#REF!,Overview!U9,#REF!) -> #REF! | AS9: =SUMIF(#REF!,Overview!U9,#REF!) -> #REF! | AT9: =AD9*$Z9*$G9 -> #REF! | AU9: =AE9*$Z9*$G9 -> #REF! | AV9: =AF9*$Z9*$G9 -> #REF! | AW9: =AG9*$Z9*$G9 -> #REF! | AX9: =AH9*$Z9*$G9 -> #REF! | AY9: =AI9*$Z9*$G9 -> #REF! | AZ9: =AJ9*$Z9*$G9 -> #REF! | BA9: =AK9*$Z9*$G9 -> #REF! | ... BI9: =AS9*$Z9*$G9 -> #REF! | BJ9: =AD9*$Z9*$H9 -> #REF! | BK9: =AE9*$Z9*$H9 -> #REF! | BL9: =AF9*$Z9*$H9 -> #REF! | BM9: =AG9*$Z9*$H9 -> #REF! | BN9: =AH9*$Z9*$H9 -> #REF! | BO9: =AI9*$Z9*$H9 -> #REF! | BP9: =AJ9*$Z9*$H9 -> #REF! | BQ9: =AK9*$Z9*$H9 -> #REF! | ... BY9: =AS9*$Z9*$H9 -> #REF! | BZ9: =AD9*$Z9*$I9 -> #REF! | CA9: =AE9*$Z9*$I9 -> #REF! | CB9: =AF9*$Z9*$I9 -> #REF! | CC9: =AG9*$Z9*$I9 -> #REF! | CD9: =AH9*$Z9*$I9 -> #REF! | CE9: =AI9*$Z9*$I9 -> #REF! | CF9: =AJ9*$Z9*$I9 -> #REF! | CG9: =AK9*$Z9*$I9 -> #REF! | ... CO9: =AS9*$Z9*$I9 -> #REF! | CP9: =SUMIF(#REF!,Overview!$U9,#REF!) -> #REF! | CQ9: =SUMIF(#REF!,Overview!$U9,#REF!) -> #REF! | CR9: =SUMIF(#REF!,Overview!$U9,#REF!) -> #REF! | CS9: =SUMIF(#REF!,Overview!$U9,#REF!) -> #REF! | CT9: =SUMIF(#REF!,Overview!$U9,#REF!) -> #REF! | CU9: =SUMIF(#REF!,Overview!$U9,#REF!) -> #REF! | CV9: =SUMIF(#REF!,Overview!$U9,#REF!) -> #REF! | CW9: =SUMIF(#REF!,Overview!$U9,#REF!) -> #REF! | ... DE9: =SUMIF(#REF!,Overview!$U9,#REF!) -> #REF!
A10: buildings_biofuel_boiler | B10: Biomass residential boiler | C10: 9.4861041 | D10: 4.2807529e-06 | E10: 5.3391328 | F10: 9.7710102 | G10: 32723.459 | H10: 0.017893374 | I10: 18237.126 | J10: 34849.916 | K10: ecoinvent 3.9.1 | L10: furnace production, wood chips, with silo, 50kW | M10: 333bd422fa2177e933445cd00b981505 | N10: CH | O10: 1.0 unit of 50kW | P10: energy_cap | Q10: buildings_biofuel_boiler_heat | R10: Lifetime of 17 years | S10: - | T10: - | U10: heat production, wood chips from industry, at furnace 50kW, Calliope | V10: af1be324a919b7f2a2c2b31b2e5064d8 | W10: CH | X10: CH | Y10: MJ | Z10: =3.6*1000000 -> 3600000 | AD10: =SUMIF(#REF!,Overview!U10,#REF!) -> #REF! | AE10: =SUMIF(#REF!,Overview!U10,#REF!) -> #REF! | AF10: =SUMIF(#REF!,Overview!U10,#REF!) -> #REF! | AG10: =SUMIF(#REF!,Overview!U10,#REF!) -> #REF! | AH10: =SUMIF(#REF!,Overview!U10,#REF!) -> #REF! | AI10: =SUMIF(#REF!,Overview!U10,#REF!) -> #REF! | AJ10: =SUMIF(#REF!,Overview!U10,#REF!) -> #REF! | AK10: =SUMIF(#REF!,Overview!U10,#REF!) -> #REF! | AL10: =SUMIF(#REF!,Overview!U10,#REF!) -> #REF! | AM10: =SUMIF(#REF!,Overview!U10,#REF!) -> #REF! | AN10: =SUMIF(#REF!,Overview!U10,#REF!) -> #REF! | AO10: =SUMIF(#REF!,Overview!U10,#REF!) -> #REF! | AP10: =SUMIF(#REF!,Overview!U10,#REF!) -> #REF! | AQ10: =SUMIF(#REF!,Overview!U10,#REF!) -> #REF! | AR10: =SUMIF(#REF!,Overview!U10,#REF!) -> #REF! | AS10: =SUMIF(#REF!,Overview!U10,#REF!) -> #REF! | AT10: =AD10*$Z10*$C10/17 -> #REF! | AU10: =AE10*$Z10*$C10/17 -> #REF! | AV10: =AF10*$Z10*$C10/17 -> #REF! | AW10: =AG10*$Z10*$C10/17 -> #REF! | AX10: =AH10*$Z10*$C10/17 -> #REF! | AY10: =AI10*$Z10*$C10/17 -> #REF! | AZ10: =AJ10*$Z10*$C10/17 -> #REF! | BA10: =AK10*$Z10*$C10/17 -> #REF! | ... BI10: =AS10*$Z10*$C10/17 -> #REF! | BJ10: =AD10*$Z10*$D10/17 -> #REF! | BK10: =AE10*$Z10*$D10/17 -> #REF! | BL10: =AF10*$Z10*$D10/17 -> #REF! | BM10: =AG10*$Z10*$D10/17 -> #REF! | BN10: =AH10*$Z10*$D10/17 -> #REF! | BO10: =AI10*$Z10*$D10/17 -> #REF! | BP10: =AJ10*$Z10*$D10/17 -> #REF! | BQ10: =AK10*$Z10*$D10/17 -> #REF! | ... BY10: =AS10*$Z10*$D10/17 -> #REF! | BZ10: =AD10*$Z10*$E10/17 -> #REF! | CA10: =AE10*$Z10*$E10/17 -> #REF! | CB10: =AF10*$Z10*$E10/17 -> #REF! | CC10: =AG10*$Z10*$E10/17 -> #REF! | CD10: =AH10*$Z10*$E10/17 -> #REF! | CE10: =AI10*$Z10*$E10/17 -> #REF! | CF10: =AJ10*$Z10*$E10/17 -> #REF! | CG10: =AK10*$Z10*$E10/17 -> #REF! | ... CO10: =AS10*$Z10*$E10/17 -> #REF! | CP10: =SUMIF(#REF!,Overview!$U10,#REF!) -> #REF! | CQ10: =SUMIF(#REF!,Overview!$U10,#REF!) -> #REF! | CR10: =SUMIF(#REF!,Overview!$U10,#REF!) -> #REF! | CS10: =SUMIF(#REF!,Overview!$U10,#REF!) -> #REF! | CT10: =SUMIF(#REF!,Overview!$U10,#REF!) -> #REF! | CU10: =SUMIF(#REF!,Overview!$U10,#REF!) -> #REF! | CV10: =SUMIF(#REF!,Overview!$U10,#REF!) -> #REF! | CW10: =SUMIF(#REF!,Overview!$U10,#REF!) -> #REF! | ... DE10: =SUMIF(#REF!,Overview!$U10,#REF!) -> #REF!
B11: Biofuel combustion | AK11: =SUMIF(#REF!,Overview!U11,#REF!) -> #REF! | AL11: =SUMIF(#REF!,Overview!U11,#REF!) -> #REF!
A12: buildings_methane_boiler | B12: Gas residential boiler | C12: 2.3131806e-05 | D12: 3.3979215e-06 | E12: 8.0582742e-06 | F12: 4.90071 | G12: 0.0082304001 | H12: 0.00033480392 | I12: 0.0038898561 | J12: 16232.878 | K12: ecoinvent 3.9.1 | L12: gas boiler production | M12: 932f861aecca8621f12e22e5f8ccb775 | N12: RER | O12: 1.0 unit of 10kW | P12: energy_cap | Q12: buildings_methane_boiler_heat | R12: lifetime of 20 years (ecoinvent) | S12: - | T12: - | U12: gas boiler production | V12: 932f861aecca8621f12e22e5f8ccb775 | W12: RER | X12: CH | Y12: unit of 10kW | Z12: 100000 | AD12: =SUMIF(#REF!,Overview!U12,#REF!) -> #REF! | AE12: =SUMIF(#REF!,Overview!U12,#REF!) -> #REF! | AF12: =SUMIF(#REF!,Overview!U12,#REF!) -> #REF! | AG12: =SUMIF(#REF!,Overview!U12,#REF!) -> #REF! | AH12: =SUMIF(#REF!,Overview!U12,#REF!) -> #REF! | AI12: =SUMIF(#REF!,Overview!U12,#REF!) -> #REF! | AJ12: =SUMIF(#REF!,Overview!U12,#REF!) -> #REF! | AK12: =SUMIF(#REF!,Overview!U12,#REF!) -> #REF! | AL12: =SUMIF(#REF!,Overview!U12,#REF!) -> #REF! | AM12: =SUMIF(#REF!,Overview!U12,#REF!) -> #REF! | AN12: =SUMIF(#REF!,Overview!U12,#REF!) -> #REF! | AO12: =SUMIF(#REF!,Overview!U12,#REF!) -> #REF! | AP12: =SUMIF(#REF!,Overview!U12,#REF!) -> #REF! | AQ12: =SUMIF(#REF!,Overview!U12,#REF!) -> #REF! | AR12: =SUMIF(#REF!,Overview!U12,#REF!) -> #REF! | AS12: =SUMIF(#REF!,Overview!U12,#REF!) -> #REF! | AT12: =AD12*$Z12*$C12/20 -> #REF! | AU12: =AE12*$Z12*$C12/20 -> #REF! | AV12: =AF12*$Z12*$C12/20 -> #REF! | AW12: =AG12*$Z12*$C12/20 -> #REF! | AX12: =AH12*$Z12*$C12/20 -> #REF! | AY12: =AI12*$Z12*$C12/20 -> #REF! | AZ12: =AJ12*$Z12*$C12/20 -> #REF! | BA12: =AK12*$Z12*$C12/20 -> #REF! | ... BI12: =AS12*$Z12*$C12/20 -> #REF! | BJ12: =AD12*$Z12*$D12/20 -> #REF! | BK12: =AE12*$Z12*$D12/20 -> #REF! | BL12: =AF12*$Z12*$D12/20 -> #REF! | BM12: =AG12*$Z12*$D12/20 -> #REF! | BN12: =AH12*$Z12*$D12/20 -> #REF! | BO12: =AI12*$Z12*$D12/20 -> #REF! | BP12: =AJ12*$Z12*$D12/20 -> #REF! | BQ12: =AK12*$Z12*$D12/20 -> #REF! | ... BY12: =AS12*$Z12*$D12/20 -> #REF! | BZ12: =AD12*$Z12*$E12/20 -> #REF! | CA12: =AE12*$Z12*$E12/20 -> #REF! | CB12: =AF12*$Z12*$E12/20 -> #REF! | CC12: =AG12*$Z12*$E12/20 -> #REF! | CD12: =AH12*$Z12*$E12/20 -> #REF! | CE12: =AI12*$Z12*$E12/20 -> #REF! | CF12: =AJ12*$Z12*$E12/20 -> #REF! | CG12: =AK12*$Z12*$E12/20 -> #REF! | ... CO12: =AS12*$Z12*$E12/20 -> #REF! | CP12: =SUMIF(#REF!,Overview!$U12,#REF!) -> #REF! | CQ12: =SUMIF(#REF!,Overview!$U12,#REF!) -> #REF! | CR12: =SUMIF(#REF!,Overview!$U12,#REF!) -> #REF! | CS12: =SUMIF(#REF!,Overview!$U12,#REF!) -> #REF! | CT12: =SUMIF(#REF!,Overview!$U12,#REF!) -> #REF! | CU12: =SUMIF(#REF!,Overview!$U12,#REF!) -> #REF! | CV12: =SUMIF(#REF!,Overview!$U12,#REF!) -> #REF! | CW12: =SUMIF(#REF!,Overview!$U12,#REF!) -> #REF! | ... DE12: =SUMIF(#REF!,Overview!$U12,#REF!) -> #REF!
A13: industry_methane_boiler | B13: Industrial gas boiler | C13: 0.64918927 | D13: 0.64917136 | E13: 0.64917704 | F13: 0.64921823 | G13: 5702.3029 | H13: 5702.2974 | I13: 5702.2973 | J13: 5702.3224 | K13: ecoinvent 3.9.1 | L13: gas boiler production | M13: 932f861aecca8621f12e22e5f8ccb775 | N13: RER | O13: 1.0 unit of 10kW | P13: energy_cap | Q13: industry_methane_boiler_heat | R13: lifetime of 20 years (ecoinvent) | S13: - | T13: - | U13: gas boiler production | V13: 932f861aecca8621f12e22e5f8ccb775 | W13: RER | X13: CH | Y13: unit of 10kW | Z13: 100000 | AD13: =SUMIF(#REF!,Overview!U13,#REF!) -> #REF! | AE13: =SUMIF(#REF!,Overview!U13,#REF!) -> #REF! | AF13: =SUMIF(#REF!,Overview!U13,#REF!) -> #REF! | AG13: =SUMIF(#REF!,Overview!U13,#REF!) -> #REF! | AH13: =SUMIF(#REF!,Overview!U13,#REF!) -> #REF! | AI13: =SUMIF(#REF!,Overview!U13,#REF!) -> #REF! | AJ13: =SUMIF(#REF!,Overview!U13,#REF!) -> #REF! | AK13: =SUMIF(#REF!,Overview!U13,#REF!) -> #REF! | AL13: =SUMIF(#REF!,Overview!U13,#REF!) -> #REF! | AM13: =SUMIF(#REF!,Overview!U13,#REF!) -> #REF! | AN13: =SUMIF(#REF!,Overview!U13,#REF!) -> #REF! | AO13: =SUMIF(#REF!,Overview!U13,#REF!) -> #REF! | AP13: =SUMIF(#REF!,Overview!U13,#REF!) -> #REF! | AQ13: =SUMIF(#REF!,Overview!U13,#REF!) -> #REF! | AR13: =SUMIF(#REF!,Overview!U13,#REF!) -> #REF! | AS13: =SUMIF(#REF!,Overview!U13,#REF!) -> #REF! | AT13: =AD13*$Z13*$C13/20 -> #REF! | AU13: =AE13*$Z13*$C13/20 -> #REF! | AV13: =AF13*$Z13*$C13/20 -> #REF! | AW13: =AG13*$Z13*$C13/20 -> #REF! | AX13: =AH13*$Z13*$C13/20 -> #REF! | AY13: =AI13*$Z13*$C13/20 -> #REF! | AZ13: =AJ13*$Z13*$C13/20 -> #REF! | BA13: =AK13*$Z13*$C13/20 -> #REF! | ... BI13: =AS13*$Z13*$C13/20 -> #REF! | CP13: =SUMIF(#REF!,Overview!$U13,#REF!) -> #REF! | CQ13: =SUMIF(#REF!,Overview!$U13,#REF!) -> #REF! | CR13: =SUMIF(#REF!,Overview!$U13,#REF!) -> #REF! | CS13: =SUMIF(#REF!,Overview!$U13,#REF!) -> #REF! | CT13: =SUMIF(#REF!,Overview!$U13,#REF!) -> #REF! | CU13: =SUMIF(#REF!,Overview!$U13,#REF!) -> #REF! | CV13: =SUMIF(#REF!,Overview!$U13,#REF!) -> #REF! | CW13: =SUMIF(#REF!,Overview!$U13,#REF!) -> #REF! | ... DE13: =SUMIF(#REF!,Overview!$U13,#REF!) -> #REF!
B14: Burning Nat Gas in Industry | S14: remove boiler / furnace production | U14: heat production, natural gas, at boiler condensing modulating >100kW, Calliope | V14: 2b3556f16b05459aa80d7288b2109c0d | W14: EUR | X14: CH | Y14: MJ | Z14: =3.6*1000000 -> 3600000 | AC14: MJ/GWh | AD14: =SUMIF(#REF!,Overview!U14,#REF!) -> #REF! | AE14: =SUMIF(#REF!,Overview!U14,#REF!) -> #REF! | AF14: =SUMIF(#REF!,Overview!U14,#REF!) -> #REF! | AG14: =SUMIF(#REF!,Overview!U14,#REF!) -> #REF! | AH14: =SUMIF(#REF!,Overview!U14,#REF!) -> #REF! | AI14: =SUMIF(#REF!,Overview!U14,#REF!) -> #REF! | AJ14: =SUMIF(#REF!,Overview!U14,#REF!) -> #REF! | AK14: =SUMIF(#REF!,Overview!U14,#REF!) -> #REF! | AL14: =SUMIF(#REF!,Overview!U14,#REF!) -> #REF! | AM14: =SUMIF(#REF!,Overview!U14,#REF!) -> #REF! | AN14: =SUMIF(#REF!,Overview!U14,#REF!) -> #REF! | AO14: =SUMIF(#REF!,Overview!U14,#REF!) -> #REF! | AP14: =SUMIF(#REF!,Overview!U14,#REF!) -> #REF! | AQ14: =SUMIF(#REF!,Overview!U14,#REF!) -> #REF! | AR14: =SUMIF(#REF!,Overview!U14,#REF!) -> #REF! | AS14: =SUMIF(#REF!,Overview!U14,#REF!) -> #REF! | CP14: =SUMIF(#REF!,Overview!$U14,#REF!) -> #REF! | CQ14: =SUMIF(#REF!,Overview!$U14,#REF!) -> #REF! | CR14: =SUMIF(#REF!,Overview!$U14,#REF!) -> #REF! | CS14: =SUMIF(#REF!,Overview!$U14,#REF!) -> #REF! | CT14: =SUMIF(#REF!,Overview!$U14,#REF!) -> #REF! | CU14: =SUMIF(#REF!,Overview!$U14,#REF!) -> #REF! | CV14: =SUMIF(#REF!,Overview!$U14,#REF!) -> #REF! | CW14: =SUMIF(#REF!,Overview!$U14,#REF!) -> #REF! | ... DE14: =SUMIF(#REF!,Overview!$U14,#REF!) -> #REF!
B15: Burning Nat Gas for Buildings | S15: remove gas boiler | U15: heat production, natural gas, at boiler atmospheric low-NOx non-modulating <100kW, Calliope | V15: e071921f48db45b68e12e39e03e49c1d | W15: EUR | X15: CH | Y15: MJ | Z15: =3.6*1000000 -> 3600000 | AC15: MJ/GWh | AD15: =SUMIF(#REF!,Overview!U15,#REF!) -> #REF! | AE15: =SUMIF(#REF!,Overview!U15,#REF!) -> #REF! | AF15: =SUMIF(#REF!,Overview!U15,#REF!) -> #REF! | AG15: =SUMIF(#REF!,Overview!U15,#REF!) -> #REF! | AH15: =SUMIF(#REF!,Overview!U15,#REF!) -> #REF! | AI15: =SUMIF(#REF!,Overview!U15,#REF!) -> #REF! | AJ15: =SUMIF(#REF!,Overview!U15,#REF!) -> #REF! | AK15: =SUMIF(#REF!,Overview!U15,#REF!) -> #REF! | AL15: =SUMIF(#REF!,Overview!U15,#REF!) -> #REF! | AM15: =SUMIF(#REF!,Overview!U15,#REF!) -> #REF! | AN15: =SUMIF(#REF!,Overview!U15,#REF!) -> #REF! | AO15: =SUMIF(#REF!,Overview!U15,#REF!) -> #REF! | AP15: =SUMIF(#REF!,Overview!U15,#REF!) -> #REF! | AQ15: =SUMIF(#REF!,Overview!U15,#REF!) -> #REF! | AR15: =SUMIF(#REF!,Overview!U15,#REF!) -> #REF! | AS15: =SUMIF(#REF!,Overview!U15,#REF!) -> #REF! | CP15: =SUMIF(#REF!,Overview!$U15,#REF!) -> #REF! | CQ15: =SUMIF(#REF!,Overview!$U15,#REF!) -> #REF! | CR15: =SUMIF(#REF!,Overview!$U15,#REF!) -> #REF! | CS15: =SUMIF(#REF!,Overview!$U15,#REF!) -> #REF! | CT15: =SUMIF(#REF!,Overview!$U15,#REF!) -> #REF! | CU15: =SUMIF(#REF!,Overview!$U15,#REF!) -> #REF! | CV15: =SUMIF(#REF!,Overview!$U15,#REF!) -> #REF! | CW15: =SUMIF(#REF!,Overview!$U15,#REF!) -> #REF! | ... DE15: =SUMIF(#REF!,Overview!$U15,#REF!) -> #REF!
A16: ccgt | B16: Methane CCGT Operation | C16: 0 | D16: 0 | E16: 1.3815019 | F16: 0 | G16: 0 | H16: 0.0017001724 | I16: 4279.3329 | J16: 0 | K16: ecoinvent 3.9.1 | L16: heat and power co-generation, natural gas, combined cycle power plant, 400MW electrical | M16: 43ec4f40c772bfa03350c522061b9ce4 | N16: DE | O16: 1.0 kilowatt hour | P16: carrier_prod | Q16: electricity | R16: 5000h of operation at full capacity per year (ecoinvent) lifetime of 25 years | S16: gas power plant construction, combined cycle, 400MW electrical (location : RER) | market for natural gas, high pressure (location : DE) Burning of methane instead nat. Gas --> lower fossil CO2 emissions | T16: Careful not to double count between production and construction of gas turbines. Using one or the other depends on the type of impact that you are looking at | U16: heat and power co-generation, natural gas, combined cycle power plant, 400MW electrical, Calliope1 | V16: 43ec4f40c772bfa03350c522061b9ce4 | W16: DE | X16: CH | Y16: kWh | Z16: 1000000 | AC16: kWh/GWh | AD16: =SUMIF(#REF!,Overview!U16,#REF!) -> #REF! | AE16: =SUMIF(#REF!,Overview!U16,#REF!) -> #REF! | AF16: =SUMIF(#REF!,Overview!U16,#REF!) -> #REF! | AG16: =SUMIF(#REF!,Overview!U16,#REF!) -> #REF! | AH16: =SUMIF(#REF!,Overview!U16,#REF!) -> #REF! | AI16: =SUMIF(#REF!,Overview!U16,#REF!) -> #REF! | AJ16: =SUMIF(#REF!,Overview!U16,#REF!) -> #REF! | AK16: =SUMIF(#REF!,Overview!U16,#REF!) -> #REF! | AL16: =SUMIF(#REF!,Overview!U16,#REF!) -> #REF! | AM16: =SUMIF(#REF!,Overview!U16,#REF!) -> #REF! | AN16: =SUMIF(#REF!,Overview!U16,#REF!) -> #REF! | AO16: =SUMIF(#REF!,Overview!U16,#REF!) -> #REF! | AP16: =SUMIF(#REF!,Overview!U16,#REF!) -> #REF! | AQ16: =SUMIF(#REF!,Overview!U16,#REF!) -> #REF! | AR16: =SUMIF(#REF!,Overview!U16,#REF!) -> #REF! | AS16: =SUMIF(#REF!,Overview!U16,#REF!) -> #REF! | AT16: =AD16*$Z16*$G16 -> #REF! | AU16: =AE16*$Z16*$G16 -> #REF! | AV16: =AF16*$Z16*$G16 -> #REF! | AW16: =AG16*$Z16*$G16 -> #REF! | AX16: =AH16*$Z16*$G16 -> #REF! | AY16: =AI16*$Z16*$G16 -> #REF! | AZ16: =AJ16*$Z16*$G16 -> #REF! | BA16: =AK16*$Z16*$G16 -> #REF! | ... BI16: =AS16*$Z16*$G16 -> #REF! | BJ16: =AD16*$Z16*$H16 -> #REF! | BK16: =AE16*$Z16*$H16 -> #REF! | BL16: =AF16*$Z16*$H16 -> #REF! | BM16: =AG16*$Z16*$H16 -> #REF! | BN16: =AH16*$Z16*$H16 -> #REF! | BO16: =AI16*$Z16*$H16 -> #REF! | BP16: =AJ16*$Z16*$H16 -> #REF! | BQ16: =AK16*$Z16*$H16 -> #REF! | ... BY16: =AS16*$Z16*$H16 -> #REF! | BZ16: =AD16*$Z16*$I16 -> #REF! | CA16: =AE16*$Z16*$I16 -> #REF! | CB16: =AF16*$Z16*$I16 -> #REF! | CC16: =AG16*$Z16*$I16 -> #REF! | CD16: =AH16*$Z16*$I16 -> #REF! | CE16: =AI16*$Z16*$I16 -> #REF! | CF16: =AJ16*$Z16*$I16 -> #REF! | CG16: =AK16*$Z16*$I16 -> #REF! | ... CO16: =AS16*$Z16*$I16 -> #REF! | CP16: =SUMIF(#REF!,Overview!$U16,#REF!) -> #REF! | CQ16: =SUMIF(#REF!,Overview!$U16,#REF!) -> #REF! | CR16: =SUMIF(#REF!,Overview!$U16,#REF!) -> #REF! | CS16: =SUMIF(#REF!,Overview!$U16,#REF!) -> #REF! | CT16: =SUMIF(#REF!,Overview!$U16,#REF!) -> #REF! | CU16: =SUMIF(#REF!,Overview!$U16,#REF!) -> #REF! | CV16: =SUMIF(#REF!,Overview!$U16,#REF!) -> #REF! | CW16: =SUMIF(#REF!,Overview!$U16,#REF!) -> #REF! | ... DE16: =SUMIF(#REF!,Overview!$U16,#REF!) -> #REF!
A17: ccgt | B17: Methane CCGT Construction | C17: 0 | D17: 0 | E17: 1.3815019 | F17: 0 | G17: 0 | H17: 0.0017001724 | I17: 4279.3329 | J17: 0 | K17: ecoinvent 3.9.1 | L17: gas power plant construction, combined cycle, 400MW electrical | M17: 249432931c0e8af8329de379cfb9c192 | N17: RER | O17: 1.0 unit of 400MW electrical | P17: energy_cap | Q17: electricity | R17: lifetime of 25 years | S17: - | U17: gas power plant construction, combined cycle, 400MW electrical | V17: 249432931c0e8af8329de379cfb9c192 | W17: RER | X17: CH | Y17: unit of 400MW | Z17: =1000/400 -> 2.5 | AD17: =SUMIF(#REF!,Overview!U17,#REF!) -> #REF! | AE17: =SUMIF(#REF!,Overview!U17,#REF!) -> #REF! | AF17: =SUMIF(#REF!,Overview!U17,#REF!) -> #REF! | AG17: =SUMIF(#REF!,Overview!U17,#REF!) -> #REF! | AH17: =SUMIF(#REF!,Overview!U17,#REF!) -> #REF! | AI17: =SUMIF(#REF!,Overview!U17,#REF!) -> #REF! | AJ17: =SUMIF(#REF!,Overview!U17,#REF!) -> #REF! | AK17: =SUMIF(#REF!,Overview!U17,#REF!) -> #REF! | AL17: =SUMIF(#REF!,Overview!U17,#REF!) -> #REF! | AM17: =SUMIF(#REF!,Overview!U17,#REF!) -> #REF! | AN17: =SUMIF(#REF!,Overview!U17,#REF!) -> #REF! | AO17: =SUMIF(#REF!,Overview!U17,#REF!) -> #REF! | AP17: =SUMIF(#REF!,Overview!U17,#REF!) -> #REF! | AQ17: =SUMIF(#REF!,Overview!U17,#REF!) -> #REF! | AR17: =SUMIF(#REF!,Overview!U17,#REF!) -> #REF! | AS17: =SUMIF(#REF!,Overview!U17,#REF!) -> #REF! | AT17: =AD17*$Z17*$C17/25 -> #REF! | AU17: =AE17*$Z17*$C17/25 -> #REF! | AV17: =AF17*$Z17*$C17/25 -> #REF! | AW17: =AG17*$Z17*$C17/25 -> #REF! | AX17: =AH17*$Z17*$C17/25 -> #REF! | AY17: =AI17*$Z17*$C17/25 -> #REF! | AZ17: =AJ17*$Z17*$C17/25 -> #REF! | BA17: =AK17*$Z17*$C17/25 -> #REF! | ... BI17: =AS17*$Z17*$C17/25 -> #REF! | BJ17: =AD17*$Z17*$D17/25 -> #REF! | BK17: =AE17*$Z17*$D17/25 -> #REF! | BL17: =AF17*$Z17*$D17/25 -> #REF! | BM17: =AG17*$Z17*$D17/25 -> #REF! | BN17: =AH17*$Z17*$D17/25 -> #REF! | BO17: =AI17*$Z17*$D17/25 -> #REF! | BP17: =AJ17*$Z17*$D17/25 -> #REF! | BQ17: =AK17*$Z17*$D17/25 -> #REF! | ... BY17: =AS17*$Z17*$D17/25 -> #REF! | BZ17: =AD17*$Z17*$E17/25 -> #REF! | CA17: =AE17*$Z17*$E17/25 -> #REF! | CB17: =AF17*$Z17*$E17/25 -> #REF! | CC17: =AG17*$Z17*$E17/25 -> #REF! | CD17: =AH17*$Z17*$E17/25 -> #REF! | CE17: =AI17*$Z17*$E17/25 -> #REF! | CF17: =AJ17*$Z17*$E17/25 -> #REF! | CG17: =AK17*$Z17*$E17/25 -> #REF! | ... CO17: =AS17*$Z17*$E17/25 -> #REF! | CP17: =SUMIF(#REF!,Overview!$U17,#REF!) -> #REF! | CQ17: =SUMIF(#REF!,Overview!$U17,#REF!) -> #REF! | CR17: =SUMIF(#REF!,Overview!$U17,#REF!) -> #REF! | CS17: =SUMIF(#REF!,Overview!$U17,#REF!) -> #REF! | CT17: =SUMIF(#REF!,Overview!$U17,#REF!) -> #REF! | CU17: =SUMIF(#REF!,Overview!$U17,#REF!) -> #REF! | CV17: =SUMIF(#REF!,Overview!$U17,#REF!) -> #REF! | CW17: =SUMIF(#REF!,Overview!$U17,#REF!) -> #REF! | ... DE17: =SUMIF(#REF!,Overview!$U17,#REF!) -> #REF!
A18: ccgt_natgas | B18: Natural Gas CCGT Operation | D18: 3.3998487 | H18: 12650.865 | K18: ecoinvent 3.9.1 | L18: heat and power co-generation, natural gas, combined cycle power plant, 400MW electrical | M18: 43ec4f40c772bfa03350c522061b9ce4 | N18: DE | O18: 1.0 kilowatt hour | P18: carrier_prod | Q18: electricity | R18: 5000h of operation at full capacity per year (ecoinvent) lifetime of 25 years | S18: gas power plant construction, combined cycle, 400MW electrical (location : RER) | market for natural gas, high pressure (location : DE) | U18: heat and power co-generation, natural gas, combined cycle power plant, 400MW electrical, Calliope2 | V18: 43ec4f40c772bfa03350c522061b9ce4 | W18: DE | X18: CH | Y18: kWh | Z18: 1000000 | AC18: kWh/GWh | AD18: =SUMIF(#REF!,Overview!U18,#REF!) -> #REF! | AE18: =SUMIF(#REF!,Overview!U18,#REF!) -> #REF! | AF18: =SUMIF(#REF!,Overview!U18,#REF!) -> #REF! | AG18: =SUMIF(#REF!,Overview!U18,#REF!) -> #REF! | AH18: =SUMIF(#REF!,Overview!U18,#REF!) -> #REF! | AI18: =SUMIF(#REF!,Overview!U18,#REF!) -> #REF! | AJ18: =SUMIF(#REF!,Overview!U18,#REF!) -> #REF! | AK18: =SUMIF(#REF!,Overview!U18,#REF!) -> #REF! | AL18: =SUMIF(#REF!,Overview!U18,#REF!) -> #REF! | AM18: =SUMIF(#REF!,Overview!U18,#REF!) -> #REF! | AN18: =SUMIF(#REF!,Overview!U18,#REF!) -> #REF! | AO18: =SUMIF(#REF!,Overview!U18,#REF!) -> #REF! | AP18: =SUMIF(#REF!,Overview!U18,#REF!) -> #REF! | AQ18: =SUMIF(#REF!,Overview!U18,#REF!) -> #REF! | AR18: =SUMIF(#REF!,Overview!U18,#REF!) -> #REF! | AS18: =SUMIF(#REF!,Overview!U18,#REF!) -> #REF! | AT18: =AD18*$Z18*$G18 -> #REF! | AU18: =AE18*$Z18*$G18 -> #REF! | AV18: =AF18*$Z18*$G18 -> #REF! | AW18: =AG18*$Z18*$G18 -> #REF! | AX18: =AH18*$Z18*$G18 -> #REF! | AY18: =AI18*$Z18*$G18 -> #REF! | AZ18: =AJ18*$Z18*$G18 -> #REF! | BA18: =AK18*$Z18*$G18 -> #REF! | ... BI18: =AS18*$Z18*$G18 -> #REF! | BJ18: =AD18*$Z18*$H18 -> #REF! | BK18: =AE18*$Z18*$H18 -> #REF! | BL18: =AF18*$Z18*$H18 -> #REF! | BM18: =AG18*$Z18*$H18 -> #REF! | BN18: =AH18*$Z18*$H18 -> #REF! | BO18: =AI18*$Z18*$H18 -> #REF! | BP18: =AJ18*$Z18*$H18 -> #REF! | BQ18: =AK18*$Z18*$H18 -> #REF! | ... BY18: =AS18*$Z18*$H18 -> #REF! | BZ18: =AD18*$Z18*$I18 -> #REF! | CA18: =AE18*$Z18*$I18 -> #REF! | CB18: =AF18*$Z18*$I18 -> #REF! | CC18: =AG18*$Z18*$I18 -> #REF! | CD18: =AH18*$Z18*$I18 -> #REF! | CE18: =AI18*$Z18*$I18 -> #REF! | CF18: =AJ18*$Z18*$I18 -> #REF! | CG18: =AK18*$Z18*$I18 -> #REF! | ... CO18: =AS18*$Z18*$I18 -> #REF! | CP18: =SUMIF(#REF!,Overview!$U18,#REF!) -> #REF! | CQ18: =SUMIF(#REF!,Overview!$U18,#REF!) -> #REF! | CR18: =SUMIF(#REF!,Overview!$U18,#REF!) -> #REF! | CS18: =SUMIF(#REF!,Overview!$U18,#REF!) -> #REF! | CT18: =SUMIF(#REF!,Overview!$U18,#REF!) -> #REF! | CU18: =SUMIF(#REF!,Overview!$U18,#REF!) -> #REF! | CV18: =SUMIF(#REF!,Overview!$U18,#REF!) -> #REF! | CW18: =SUMIF(#REF!,Overview!$U18,#REF!) -> #REF! | ... DE18: =SUMIF(#REF!,Overview!$U18,#REF!) -> #REF!
A19: ccgt_natgas | B19: Natural Gas CCGT Construction | D19: 3.3998487 | H19: 12650.865 | K19: ecoinvent 3.9.1 | L19: gas power plant construction, combined cycle, 400MW electrical | M19: 249432931c0e8af8329de379cfb9c192 | N19: RER | O19: 1.0 unit of 400MW electrical | P19: energy_cap | Q19: electricity | R19: lifetime of 25 years | S19: - | U19: gas power plant construction, combined cycle, 400MW electrical | V19: 249432931c0e8af8329de379cfb9c192 | W19: RER | X19: CH | Y19: unit of 400MW | Z19: =1000/400 -> 2.5 | AD19: =SUMIF(#REF!,Overview!U19,#REF!) -> #REF! | AE19: =SUMIF(#REF!,Overview!U19,#REF!) -> #REF! | AF19: =SUMIF(#REF!,Overview!U19,#REF!) -> #REF! | AG19: =SUMIF(#REF!,Overview!U19,#REF!) -> #REF! | AH19: =SUMIF(#REF!,Overview!U19,#REF!) -> #REF! | AI19: =SUMIF(#REF!,Overview!U19,#REF!) -> #REF! | AJ19: =SUMIF(#REF!,Overview!U19,#REF!) -> #REF! | AK19: =SUMIF(#REF!,Overview!U19,#REF!) -> #REF! | AL19: =SUMIF(#REF!,Overview!U19,#REF!) -> #REF! | AM19: =SUMIF(#REF!,Overview!U19,#REF!) -> #REF! | AN19: =SUMIF(#REF!,Overview!U19,#REF!) -> #REF! | AO19: =SUMIF(#REF!,Overview!U19,#REF!) -> #REF! | AP19: =SUMIF(#REF!,Overview!U19,#REF!) -> #REF! | AQ19: =SUMIF(#REF!,Overview!U19,#REF!) -> #REF! | AR19: =SUMIF(#REF!,Overview!U19,#REF!) -> #REF! | AS19: =SUMIF(#REF!,Overview!U19,#REF!) -> #REF! | AT19: =AD19*$Z19*$C19/25 -> #REF! | AU19: =AE19*$Z19*$C19/25 -> #REF! | AV19: =AF19*$Z19*$C19/25 -> #REF! | AW19: =AG19*$Z19*$C19/25 -> #REF! | AX19: =AH19*$Z19*$C19/25 -> #REF! | AY19: =AI19*$Z19*$C19/25 -> #REF! | AZ19: =AJ19*$Z19*$C19/25 -> #REF! | BA19: =AK19*$Z19*$C19/25 -> #REF! | ... BI19: =AS19*$Z19*$C19/25 -> #REF! | BJ19: =AD19*$Z19*$D19/25 -> #REF! | BK19: =AE19*$Z19*$D19/25 -> #REF! | BL19: =AF19*$Z19*$D19/25 -> #REF! | BM19: =AG19*$Z19*$D19/25 -> #REF! | BN19: =AH19*$Z19*$D19/25 -> #REF! | BO19: =AI19*$Z19*$D19/25 -> #REF! | BP19: =AJ19*$Z19*$D19/25 -> #REF! | BQ19: =AK19*$Z19*$D19/25 -> #REF! | ... BY19: =AS19*$Z19*$D19/25 -> #REF! | BZ19: =AD19*$Z19*$E19/25 -> #REF! | CA19: =AE19*$Z19*$E19/25 -> #REF! | CB19: =AF19*$Z19*$E19/25 -> #REF! | CC19: =AG19*$Z19*$E19/25 -> #REF! | CD19: =AH19*$Z19*$E19/25 -> #REF! | CE19: =AI19*$Z19*$E19/25 -> #REF! | CF19: =AJ19*$Z19*$E19/25 -> #REF! | CG19: =AK19*$Z19*$E19/25 -> #REF! | ... CO19: =AS19*$Z19*$E19/25 -> #REF! | CP19: =SUMIF(#REF!,Overview!$U19,#REF!) -> #REF! | CQ19: =SUMIF(#REF!,Overview!$U19,#REF!) -> #REF! | CR19: =SUMIF(#REF!,Overview!$U19,#REF!) -> #REF! | CS19: =SUMIF(#REF!,Overview!$U19,#REF!) -> #REF! | CT19: =SUMIF(#REF!,Overview!$U19,#REF!) -> #REF! | CU19: =SUMIF(#REF!,Overview!$U19,#REF!) -> #REF! | CV19: =SUMIF(#REF!,Overview!$U19,#REF!) -> #REF! | CW19: =SUMIF(#REF!,Overview!$U19,#REF!) -> #REF! | ... DE19: =SUMIF(#REF!,Overview!$U19,#REF!) -> #REF!
A20: chp_biofuel | B20: Biomass CHP | C20: 4.1362672e-06 | D20: 0 | E20: 0.002974905 | F20: 8.4539284e-06 | G20: 0.007589742 | H20: 0.0048097689 | I20: 26.123956 | J20: 0.0083189167 | K20: ecoinvent 3.9.1 | L20: heat and power co-generation unit construction, organic Rankine cycle, 200kW electrical | M20: ace643181d83fb151fc1f647dce7a328 | N20: GLO | O20: 1.0 unit of 200kW electrical | P20: energy_cap | Q20: electricity | R20: lifetime of 25 years | S20: - | T20: - | U20: heat and power co-generation, wood chips, 2000 kW, Calliope | V20: 39b64dccc9feaf12db32b24a4dd4fc2a | W20: CH | X20: CH | Y20: kWh | Z20: 1000000 | AD20: =SUMIF(#REF!,Overview!U20,#REF!) -> #REF! | AE20: =SUMIF(#REF!,Overview!U20,#REF!) -> #REF! | AF20: =SUMIF(#REF!,Overview!U20,#REF!) -> #REF! | AG20: =SUMIF(#REF!,Overview!U20,#REF!) -> #REF! | AH20: =SUMIF(#REF!,Overview!U20,#REF!) -> #REF! | AI20: =SUMIF(#REF!,Overview!U20,#REF!) -> #REF! | AJ20: =SUMIF(#REF!,Overview!U20,#REF!) -> #REF! | AK20: =SUMIF(#REF!,Overview!U20,#REF!) -> #REF! | AL20: =SUMIF(#REF!,Overview!U20,#REF!) -> #REF! | AM20: =SUMIF(#REF!,Overview!U20,#REF!) -> #REF! | AN20: =SUMIF(#REF!,Overview!U20,#REF!) -> #REF! | AO20: =SUMIF(#REF!,Overview!U20,#REF!) -> #REF! | AP20: =SUMIF(#REF!,Overview!U20,#REF!) -> #REF! | AQ20: =SUMIF(#REF!,Overview!U20,#REF!) -> #REF! | AR20: =SUMIF(#REF!,Overview!U20,#REF!) -> #REF! | AS20: =SUMIF(#REF!,Overview!U20,#REF!) -> #REF! | AT20: =AD20*$Z20*$C20/25 -> #REF! | AU20: =AE20*$Z20*$C20/25 -> #REF! | AV20: =AF20*$Z20*$C20/25 -> #REF! | AW20: =AG20*$Z20*$C20/25 -> #REF! | AX20: =AH20*$Z20*$C20/25 -> #REF! | AY20: =AI20*$Z20*$C20/25 -> #REF! | AZ20: =AJ20*$Z20*$C20/25 -> #REF! | BA20: =AK20*$Z20*$C20/25 -> #REF! | ... BI20: =AS20*$Z20*$C20/25 -> #REF! | BJ20: =AD20*$Z20*$D20/25 -> #REF! | BK20: =AE20*$Z20*$D20/25 -> #REF! | BL20: =AF20*$Z20*$D20/25 -> #REF! | BM20: =AG20*$Z20*$D20/25 -> #REF! | BN20: =AH20*$Z20*$D20/25 -> #REF! | BO20: =AI20*$Z20*$D20/25 -> #REF! | BP20: =AJ20*$Z20*$D20/25 -> #REF! | BQ20: =AK20*$Z20*$D20/25 -> #REF! | ... BY20: =AS20*$Z20*$D20/25 -> #REF! | BZ20: =AD20*$Z20*$E20/25 -> #REF! | CA20: =AE20*$Z20*$E20/25 -> #REF! | CB20: =AF20*$Z20*$E20/25 -> #REF! | CC20: =AG20*$Z20*$E20/25 -> #REF! | CD20: =AH20*$Z20*$E20/25 -> #REF! | CE20: =AI20*$Z20*$E20/25 -> #REF! | CF20: =AJ20*$Z20*$E20/25 -> #REF! | CG20: =AK20*$Z20*$E20/25 -> #REF! | ... CO20: =AS20*$Z20*$E20/25 -> #REF! | CP20: =SUMIF(#REF!,Overview!$U20,#REF!) -> #REF! | CQ20: =SUMIF(#REF!,Overview!$U20,#REF!) -> #REF! | CR20: =SUMIF(#REF!,Overview!$U20,#REF!) -> #REF! | CS20: =SUMIF(#REF!,Overview!$U20,#REF!) -> #REF! | CT20: =SUMIF(#REF!,Overview!$U20,#REF!) -> #REF! | CU20: =SUMIF(#REF!,Overview!$U20,#REF!) -> #REF! | CV20: =SUMIF(#REF!,Overview!$U20,#REF!) -> #REF! | CW20: =SUMIF(#REF!,Overview!$U20,#REF!) -> #REF! | ... DE20: =SUMIF(#REF!,Overview!$U20,#REF!) -> #REF!
A21: chp_methane | B21: Methane CHP | C21: 0.67944059 | D21: 0 | E21: 3.0506444e-06 | F21: 0.67903385 | G21: 2451.8031 | H21: 0.0020376544 | I21: 0.01612777 | J21: 2451.82 | K21: ecoinvent 3.9.1 | L21: biomethane, low pressure burned in micro gas turbine 100kWe | M21: 0f552d818f2779a396c7a5f701baba3a | N21: CH | O21: 1.0 kilowatt hour | P21: carrier_prod | Q21: electricity | R21: lifetime of 20 years | S21: market for biomethane, low pressure (location : CH) | T21: - | U21: biomethane, low pressure burned in micro gas turbine 100kWe, Calliope | V21: 0f552d818f2779a396c7a5f701baba3a | W21: CH | X21: CH | Y21: kWh | Z21: 1000000 | AC21: kWh/GWh | AD21: =SUMIF(#REF!,Overview!U21,#REF!) -> #REF! | AE21: =SUMIF(#REF!,Overview!U21,#REF!) -> #REF! | AF21: =SUMIF(#REF!,Overview!U21,#REF!) -> #REF! | AG21: =SUMIF(#REF!,Overview!U21,#REF!) -> #REF! | AH21: =SUMIF(#REF!,Overview!U21,#REF!) -> #REF! | AI21: =SUMIF(#REF!,Overview!U21,#REF!) -> #REF! | AJ21: =SUMIF(#REF!,Overview!U21,#REF!) -> #REF! | AK21: =SUMIF(#REF!,Overview!U21,#REF!) -> #REF! | AL21: =SUMIF(#REF!,Overview!U21,#REF!) -> #REF! | AM21: =SUMIF(#REF!,Overview!U21,#REF!) -> #REF! | AN21: =SUMIF(#REF!,Overview!U21,#REF!) -> #REF! | AO21: =SUMIF(#REF!,Overview!U21,#REF!) -> #REF! | AP21: =SUMIF(#REF!,Overview!U21,#REF!) -> #REF! | AQ21: =SUMIF(#REF!,Overview!U21,#REF!) -> #REF! | AR21: =SUMIF(#REF!,Overview!U21,#REF!) -> #REF! | AS21: =SUMIF(#REF!,Overview!U21,#REF!) -> #REF! | AT21: =AD21*$Z21*$G21 -> #REF! | AU21: =AE21*$Z21*$G21 -> #REF! | AV21: =AF21*$Z21*$G21 -> #REF! | AW21: =AG21*$Z21*$G21 -> #REF! | AX21: =AH21*$Z21*$G21 -> #REF! | AY21: =AI21*$Z21*$G21 -> #REF! | AZ21: =AJ21*$Z21*$G21 -> #REF! | BA21: =AK21*$Z21*$G21 -> #REF! | ... BI21: =AS21*$Z21*$G21 -> #REF! | BJ21: =AD21*$Z21*$H21 -> #REF! | BK21: =AE21*$Z21*$H21 -> #REF! | BL21: =AF21*$Z21*$H21 -> #REF! | BM21: =AG21*$Z21*$H21 -> #REF! | BN21: =AH21*$Z21*$H21 -> #REF! | BO21: =AI21*$Z21*$H21 -> #REF! | BP21: =AJ21*$Z21*$H21 -> #REF! | BQ21: =AK21*$Z21*$H21 -> #REF! | ... BY21: =AS21*$Z21*$H21 -> #REF! | BZ21: =AD21*$Z21*$I21 -> #REF! | CA21: =AE21*$Z21*$I21 -> #REF! | CB21: =AF21*$Z21*$I21 -> #REF! | CC21: =AG21*$Z21*$I21 -> #REF! | CD21: =AH21*$Z21*$I21 -> #REF! | CE21: =AI21*$Z21*$I21 -> #REF! | CF21: =AJ21*$Z21*$I21 -> #REF! | CG21: =AK21*$Z21*$I21 -> #REF! | ... CO21: =AS21*$Z21*$I21 -> #REF! | CP21: =SUMIF(#REF!,Overview!$U21,#REF!) -> #REF! | CQ21: =SUMIF(#REF!,Overview!$U21,#REF!) -> #REF! | CR21: =SUMIF(#REF!,Overview!$U21,#REF!) -> #REF! | CS21: =SUMIF(#REF!,Overview!$U21,#REF!) -> #REF! | CT21: =SUMIF(#REF!,Overview!$U21,#REF!) -> #REF! | CU21: =SUMIF(#REF!,Overview!$U21,#REF!) -> #REF! | CV21: =SUMIF(#REF!,Overview!$U21,#REF!) -> #REF! | CW21: =SUMIF(#REF!,Overview!$U21,#REF!) -> #REF! | ... DE21: =SUMIF(#REF!,Overview!$U21,#REF!) -> #REF!
A22: chp_waste | B22: Waste CHP | C22: 0.30622229 | D22: 0.30612522 | E22: 0.30612532 | F22: 0.30622268 | G22: 2688.9987 | H22: 2689.0001 | I22: 2689.0004 | J22: 2688.993 | K22: ecoinvent 3.9.1 | L22: heat and power co-generation unit construction, organic Rankine cycle, 200kW electrical | M22: ace643181d83fb151fc1f647dce7a328 | N22: GLO | O22: 1.0 unit of 200kW electrical | P22: energy_cap | Q22: electricity | R22: lifetime of 25 years | S22: - | T22: - | U22: heat and power co-generation unit construction, organic Rankine cycle, 200kW electrical | V22: ace643181d83fb151fc1f647dce7a328 | W22: GLO | X22: CH | Y22: unit of 200kW | Z22: =1000000/200 -> 5000 | AD22: =SUMIF(#REF!,Overview!U22,#REF!) -> #REF! | AE22: =SUMIF(#REF!,Overview!U22,#REF!) -> #REF! | AF22: =SUMIF(#REF!,Overview!U22,#REF!) -> #REF! | AG22: =SUMIF(#REF!,Overview!U22,#REF!) -> #REF! | AH22: =SUMIF(#REF!,Overview!U22,#REF!) -> #REF! | AI22: =SUMIF(#REF!,Overview!U22,#REF!) -> #REF! | AJ22: =SUMIF(#REF!,Overview!U22,#REF!) -> #REF! | AK22: =SUMIF(#REF!,Overview!U22,#REF!) -> #REF! | AL22: =SUMIF(#REF!,Overview!U22,#REF!) -> #REF! | AM22: =SUMIF(#REF!,Overview!U22,#REF!) -> #REF! | AN22: =SUMIF(#REF!,Overview!U22,#REF!) -> #REF! | AO22: =SUMIF(#REF!,Overview!U22,#REF!) -> #REF! | AP22: =SUMIF(#REF!,Overview!U22,#REF!) -> #REF! | AQ22: =SUMIF(#REF!,Overview!U22,#REF!) -> #REF! | AR22: =SUMIF(#REF!,Overview!U22,#REF!) -> #REF! | AS22: =SUMIF(#REF!,Overview!U22,#REF!) -> #REF! | AT22: =AD22*$Z22*$C22/25 -> #REF! | AU22: =AE22*$Z22*$C22/25 -> #REF! | AV22: =AF22*$Z22*$C22/25 -> #REF! | AW22: =AG22*$Z22*$C22/25 -> #REF! | AX22: =AH22*$Z22*$C22/25 -> #REF! | AY22: =AI22*$Z22*$C22/25 -> #REF! | AZ22: =AJ22*$Z22*$C22/25 -> #REF! | BA22: =AK22*$Z22*$C22/25 -> #REF! | ... BI22: =AS22*$Z22*$C22/25 -> #REF! | BJ22: =AD22*$Z22*$D22/25 -> #REF! | BK22: =AE22*$Z22*$D22/25 -> #REF! | BL22: =AF22*$Z22*$D22/25 -> #REF! | BM22: =AG22*$Z22*$D22/25 -> #REF! | BN22: =AH22*$Z22*$D22/25 -> #REF! | BO22: =AI22*$Z22*$D22/25 -> #REF! | BP22: =AJ22*$Z22*$D22/25 -> #REF! | BQ22: =AK22*$Z22*$D22/25 -> #REF! | ... BY22: =AS22*$Z22*$D22/25 -> #REF! | BZ22: =AD22*$Z22*$E22/25 -> #REF! | CA22: =AE22*$Z22*$E22/25 -> #REF! | CB22: =AF22*$Z22*$E22/25 -> #REF! | CC22: =AG22*$Z22*$E22/25 -> #REF! | CD22: =AH22*$Z22*$E22/25 -> #REF! | CE22: =AI22*$Z22*$E22/25 -> #REF! | CF22: =AJ22*$Z22*$E22/25 -> #REF! | CG22: =AK22*$Z22*$E22/25 -> #REF! | ... CO22: =AS22*$Z22*$E22/25 -> #REF! | CP22: =SUMIF(#REF!,Overview!$U22,#REF!) -> #REF! | CQ22: =SUMIF(#REF!,Overview!$U22,#REF!) -> #REF! | CR22: =SUMIF(#REF!,Overview!$U22,#REF!) -> #REF! | CS22: =SUMIF(#REF!,Overview!$U22,#REF!) -> #REF! | CT22: =SUMIF(#REF!,Overview!$U22,#REF!) -> #REF! | CU22: =SUMIF(#REF!,Overview!$U22,#REF!) -> #REF! | CV22: =SUMIF(#REF!,Overview!$U22,#REF!) -> #REF! | CW22: =SUMIF(#REF!,Overview!$U22,#REF!) -> #REF! | ... DE22: =SUMIF(#REF!,Overview!$U22,#REF!) -> #REF!
A23: dac | B23: DAC | C23: 16.703494 | D23: 162.97089 | E23: 16.702206 | F23: 291.56791 | G23: 73357.327 | H23: 680567.03 | I23: 71476.792 | J23: 2425150.7 | K23: Custom using ecoinvent 3.9.1 & simapro | L23: - | M23: - | N23: - | O23: 1 kg of CO2 captured | P23: carrier_prod | Q23: co2 | R23: lifetime of 20 years (ecoinvent) | S23: - | T23: This was not available in ecoinvent but is likely in Premise | U23: carbon dioxide, captured from atmosphere, with a solvent-based direct air capture system, 1MtCO2 | V23: b29c395ccd1246c0abbc98c28e8d119c | W23: RER | X23: CH | Y23: kg | AB23: 1000 | AD23: =SUMIF(#REF!,Overview!U23,#REF!)-1 -> #REF! | AE23: =SUMIF(#REF!,Overview!U23,#REF!) -> #REF! | AF23: =SUMIF(#REF!,Overview!U23,#REF!) -> #REF! | AG23: =SUMIF(#REF!,Overview!U23,#REF!) -> #REF! | AH23: =SUMIF(#REF!,Overview!U23,#REF!) -> #REF! | AI23: =SUMIF(#REF!,Overview!U23,#REF!) -> #REF! | AJ23: =SUMIF(#REF!,Overview!U23,#REF!) -> #REF! | AK23: =SUMIF(#REF!,Overview!U23,#REF!) -> #REF! | AL23: =SUMIF(#REF!,Overview!U23,#REF!) -> #REF! | AM23: =SUMIF(#REF!,Overview!U23,#REF!) -> #REF! | AN23: =SUMIF(#REF!,Overview!U23,#REF!) -> #REF! | AO23: =SUMIF(#REF!,Overview!U23,#REF!) -> #REF! | AP23: =SUMIF(#REF!,Overview!U23,#REF!) -> #REF! | AQ23: =SUMIF(#REF!,Overview!U23,#REF!) -> #REF! | AR23: =SUMIF(#REF!,Overview!U23,#REF!) -> #REF! | AS23: =SUMIF(#REF!,Overview!U23,#REF!) -> #REF! | AT23: =AD23*$AB23*$G23 -> #REF! | AU23: =AE23*$AB23*$G23 -> #REF! | AV23: =AF23*$AB23*$G23 -> #REF! | AW23: =AG23*$AB23*$G23 -> #REF! | AX23: =AH23*$AB23*$G23 -> #REF! | AY23: =AI23*$AB23*$G23 -> #REF! | AZ23: =AJ23*$AB23*$G23 -> #REF! | BA23: =AK23*$AB23*$G23 -> #REF! | ... BI23: =AS23*$AB23*$G23 -> #REF! | BJ23: =AD23*$AB23*$H23 -> #REF! | BK23: =AE23*$AB23*$H23 -> #REF! | BL23: =AF23*$AB23*$H23 -> #REF! | BM23: =AG23*$AB23*$H23 -> #REF! | BN23: =AH23*$AB23*$H23 -> #REF! | BO23: =AI23*$AB23*$H23 -> #REF! | BP23: =AJ23*$AB23*$H23 -> #REF! | BQ23: =AK23*$AB23*$H23 -> #REF! | ... BY23: =AS23*$AB23*$H23 -> #REF! | BZ23: =AD23*$AB23*$I23 -> #REF! | CA23: =AE23*$AB23*$I23 -> #REF! | CB23: =AF23*$AB23*$I23 -> #REF! | CC23: =AG23*$AB23*$I23 -> #REF! | CD23: =AH23*$AB23*$I23 -> #REF! | CE23: =AI23*$AB23*$I23 -> #REF! | CF23: =AJ23*$AB23*$I23 -> #REF! | CG23: =AK23*$AB23*$I23 -> #REF! | ... CO23: =AS23*$AB23*$I23 -> #REF! | CP23: =(SUMIF(#REF!,Overview!$U23,#REF!))-1 -> #REF! | CQ23: =SUMIF(#REF!,Overview!$U23,#REF!) -> #REF! | CR23: =SUMIF(#REF!,Overview!$U23,#REF!) -> #REF! | CS23: =SUMIF(#REF!,Overview!$U23,#REF!) -> #REF! | CT23: =SUMIF(#REF!,Overview!$U23,#REF!) -> #REF! | CU23: =SUMIF(#REF!,Overview!$U23,#REF!) -> #REF! | CV23: =SUMIF(#REF!,Overview!$U23,#REF!) -> #REF! | CW23: =SUMIF(#REF!,Overview!$U23,#REF!) -> #REF! | CX23: =SUMIF(#REF!,Overview!$U23,#REF!) -> #REF! | ... DE23: =SUMIF(#REF!,Overview!$U23,#REF!) -> #REF!
A24: daccs_local | B24: DACCS | D24: 319.05553 | H24: 2266282.5 | K24: Custom using ecoinvent 3.9.1 & simapro | L24: - | M24: - | N24: - | O24: 1 kg of CO2 captured | P24: carrier_prod | Q24: sequestered_carbon | R24: lifetime of 20 years (ecoinvent) | S24: - | T24: This was not available in ecoinvent but is likely in Premise | U24: carbon dioxide, captured from atmosphere and stored, with a solvent-based direct air capture system, 1MtCO2 | V24: 8a743f868b814179951e2ee3dcba42ef | W24: RER | X24: CH | Y24: kg | AB24: 1000 | AD24: =SUMIF(#REF!,Overview!U24,#REF!)-1 -> #REF! | AE24: =SUMIF(#REF!,Overview!U24,#REF!) -> #REF! | AF24: =SUMIF(#REF!,Overview!U24,#REF!) -> #REF! | AG24: =SUMIF(#REF!,Overview!U24,#REF!) -> #REF! | AH24: =SUMIF(#REF!,Overview!U24,#REF!) -> #REF! | AI24: =SUMIF(#REF!,Overview!U24,#REF!) -> #REF! | AJ24: =SUMIF(#REF!,Overview!U24,#REF!) -> #REF! | AK24: =SUMIF(#REF!,Overview!U24,#REF!) -> #REF! | AL24: =SUMIF(#REF!,Overview!U24,#REF!) -> #REF! | AM24: =SUMIF(#REF!,Overview!U24,#REF!) -> #REF! | AN24: =SUMIF(#REF!,Overview!U24,#REF!) -> #REF! | AO24: =SUMIF(#REF!,Overview!U24,#REF!) -> #REF! | AP24: =SUMIF(#REF!,Overview!U24,#REF!) -> #REF! | AQ24: =SUMIF(#REF!,Overview!U24,#REF!) -> #REF! | AR24: =SUMIF(#REF!,Overview!U24,#REF!) -> #REF! | AS24: =SUMIF(#REF!,Overview!U24,#REF!) -> #REF! | AT24: =AD24*$AB24*$G24 -> #REF! | AU24: =AE24*$AB24*$G24 -> #REF! | AV24: =AF24*$AB24*$G24 -> #REF! | AW24: =AG24*$AB24*$G24 -> #REF! | AX24: =AH24*$AB24*$G24 -> #REF! | AY24: =AI24*$AB24*$G24 -> #REF! | AZ24: =AJ24*$AB24*$G24 -> #REF! | BA24: =AK24*$AB24*$G24 -> #REF! | ... BI24: =AS24*$AB24*$G24 -> #REF! | BJ24: =AD24*$AB24*$H24 -> #REF! | BK24: =AE24*$AB24*$H24 -> #REF! | BL24: =AF24*$AB24*$H24 -> #REF! | BM24: =AG24*$AB24*$H24 -> #REF! | BN24: =AH24*$AB24*$H24 -> #REF! | BO24: =AI24*$AB24*$H24 -> #REF! | BP24: =AJ24*$AB24*$H24 -> #REF! | BQ24: =AK24*$AB24*$H24 -> #REF! | ... BY24: =AS24*$AB24*$H24 -> #REF! | BZ24: =AD24*$AB24*$I24 -> #REF! | CA24: =AE24*$AB24*$I24 -> #REF! | CB24: =AF24*$AB24*$I24 -> #REF! | CC24: =AG24*$AB24*$I24 -> #REF! | CD24: =AH24*$AB24*$I24 -> #REF! | CE24: =AI24*$AB24*$I24 -> #REF! | CF24: =AJ24*$AB24*$I24 -> #REF! | CG24: =AK24*$AB24*$I24 -> #REF! | ... CO24: =AS24*$AB24*$I24 -> #REF! | CP24: =(SUMIF(#REF!,Overview!$U24,#REF!))-1 -> #REF! | CQ24: =SUMIF(#REF!,Overview!$U24,#REF!) -> #REF! | CR24: =SUMIF(#REF!,Overview!$U24,#REF!) -> #REF! | CS24: =SUMIF(#REF!,Overview!$U24,#REF!) -> #REF! | CT24: =SUMIF(#REF!,Overview!$U24,#REF!) -> #REF! | CU24: =SUMIF(#REF!,Overview!$U24,#REF!) -> #REF! | CV24: =SUMIF(#REF!,Overview!$U24,#REF!) -> #REF! | CW24: =SUMIF(#REF!,Overview!$U24,#REF!) -> #REF! | CX24: =SUMIF(#REF!,Overview!$U24,#REF!) -> #REF! | ... DE24: =SUMIF(#REF!,Overview!$U24,#REF!) -> #REF!
A25: electric_heater | B25: Residential electric heating | C25: 0.00010152436 | D25: 1.2937629e-05 | E25: 3.5613685e-05 | F25: 0.00022127505 | G25: 0.0061244737 | H25: 0.00092607765 | I25: 0.0052418564 | J25: 0.026182431 | K25: ecoinvent 3.9.1 | L25: auxiliary heating unit production, electric, 5kW | M25: 3f0a21679010888d09c1dbcfb2419a60 | N25: CH | O25: 1.0 unit of 5kW | P25: energy_cap | Q25: electric_heater_heat | R25: lifetime of 15 years | S25: - | T25: - | U25: auxiliary heating unit production, electric, 5kW | V25: 3f0a21679010888d09c1dbcfb2419a60 | W25: CH | X25: CH | Y25: unit of 5kW | Z25: =1000000/5 -> 200000 | AD25: =SUMIF(#REF!,Overview!U25,#REF!) -> #REF! | AE25: =SUMIF(#REF!,Overview!U25,#REF!) -> #REF! | AF25: =SUMIF(#REF!,Overview!U25,#REF!) -> #REF! | AG25: =SUMIF(#REF!,Overview!U25,#REF!) -> #REF! | AH25: =SUMIF(#REF!,Overview!U25,#REF!) -> #REF! | AI25: =SUMIF(#REF!,Overview!U25,#REF!) -> #REF! | AJ25: =SUMIF(#REF!,Overview!U25,#REF!) -> #REF! | AK25: =SUMIF(#REF!,Overview!U25,#REF!) -> #REF! | AL25: =SUMIF(#REF!,Overview!U25,#REF!) -> #REF! | AM25: =SUMIF(#REF!,Overview!U25,#REF!) -> #REF! | AN25: =SUMIF(#REF!,Overview!U25,#REF!) -> #REF! | AO25: =SUMIF(#REF!,Overview!U25,#REF!) -> #REF! | AP25: =SUMIF(#REF!,Overview!U25,#REF!) -> #REF! | AQ25: =SUMIF(#REF!,Overview!U25,#REF!) -> #REF! | AR25: =SUMIF(#REF!,Overview!U25,#REF!) -> #REF! | AS25: =SUMIF(#REF!,Overview!U25,#REF!) -> #REF! | AT25: =AD25*$Z25*$C25/15 -> #REF! | AU25: =AE25*$Z25*$C25/15 -> #REF! | AV25: =AF25*$Z25*$C25/15 -> #REF! | AW25: =AG25*$Z25*$C25/15 -> #REF! | AX25: =AH25*$Z25*$C25/15 -> #REF! | AY25: =AI25*$Z25*$C25/15 -> #REF! | AZ25: =AJ25*$Z25*$C25/15 -> #REF! | BA25: =AK25*$Z25*$C25/15 -> #REF! | ... BI25: =AS25*$Z25*$C25/15 -> #REF! | BJ25: =AD25*$Z25*$D25/15 -> #REF! | BK25: =AE25*$Z25*$D25/15 -> #REF! | BL25: =AF25*$Z25*$D25/15 -> #REF! | BM25: =AG25*$Z25*$D25/15 -> #REF! | BN25: =AH25*$Z25*$D25/15 -> #REF! | BO25: =AI25*$Z25*$D25/15 -> #REF! | BP25: =AJ25*$Z25*$D25/15 -> #REF! | BQ25: =AK25*$Z25*$D25/15 -> #REF! | ... BY25: =AS25*$Z25*$D25/15 -> #REF! | BZ25: =AD25*$Z25*$E25/15 -> #REF! | CA25: =AE25*$Z25*$E25/15 -> #REF! | CB25: =AF25*$Z25*$E25/15 -> #REF! | CC25: =AG25*$Z25*$E25/15 -> #REF! | CD25: =AH25*$Z25*$E25/15 -> #REF! | CE25: =AI25*$Z25*$E25/15 -> #REF! | CF25: =AJ25*$Z25*$E25/15 -> #REF! | CG25: =AK25*$Z25*$E25/15 -> #REF! | ... CO25: =AS25*$Z25*$E25/15 -> #REF! | CP25: =SUMIF(#REF!,Overview!$U25,#REF!) -> #REF! | CQ25: =SUMIF(#REF!,Overview!$U25,#REF!) -> #REF! | CR25: =SUMIF(#REF!,Overview!$U25,#REF!) -> #REF! | CS25: =SUMIF(#REF!,Overview!$U25,#REF!) -> #REF! | CT25: =SUMIF(#REF!,Overview!$U25,#REF!) -> #REF! | CU25: =SUMIF(#REF!,Overview!$U25,#REF!) -> #REF! | CV25: =SUMIF(#REF!,Overview!$U25,#REF!) -> #REF! | CW25: =SUMIF(#REF!,Overview!$U25,#REF!) -> #REF! | ... DE25: =SUMIF(#REF!,Overview!$U25,#REF!) -> #REF!
